Tất nay! Xử lý lỗi trong JavaScript là quá trình xử lý các lỗi xảy ra trong quá trình thực thi mã. Điều này giúp điều hướng, quản lý và xử lý các tình huống không mong muốn một cách kiểm soát.

### Xử lý lỗi trong JavaScript:

#### Sử dụng Try...Catch:

Cú pháp `try...catch` cho phép bạn thực thi mã và xử lý các lỗi nếu chúng xảy ra trong khối mã được bao bọc bởi `try`.

Ví dụ:

```javascript
try {
  // Mã có thể gây lỗi
  let result = 10 / 0; // Gây ra lỗi chia cho 0
  console.log(result); // Dòng này không được thực thi
} catch (error) {
  // Xử lý lỗi
  console.error("Đã xảy ra lỗi: " + error.message);
}
```

#### Sử dụng Finally:

Khối `finally` trong JavaScript được sử dụng để thực hiện mã sau khi khối `try...catch` hoàn thành, bất kể có lỗi xảy ra hay không.

Ví dụ:

```javascript
try {
  // Mã có thể gây lỗi
  console.log("Thực hiện mã trong khối try");
} catch (error) {
  console.error("Đã xảy ra lỗi: " + error.message);
} finally {
  console.log("Mã trong khối finally luôn được thực hiện");
}
```

### Ví dụ tổng hợp:

```javascript
function divide(a, b) {
  try {
    if (b === 0) {
      throw new Error("Không thể chia cho 0");
    }
    return a / b;
  } catch (error) {
    console.error("Lỗi xảy ra: " + error.message);
  } finally {
    console.log("Hàm divide đã được thực hiện");
  }
}

console.log(divide(10, 2)); // Kết quả: 5
console.log(divide(10, 0)); // Hiển thị lỗi và thông báo từ catch block
```

Trong ví dụ này, `divide` là một hàm chia hai số và kiểm tra nếu số bị chia là 0, nó sẽ tạo ra một lỗi bằng cách sử dụng `throw new Error()`. Sau đó, hàm này sẽ được bao quanh bởi một khối `try...catch` để xử lý lỗi và in ra thông báo tương ứng.

Xử lý lỗi là một phần quan trọng của việc viết mã JavaScript an toàn và ổn định, giúp bạn kiểm soát và xử lý các tình huống không mong muốn một cách linh hoạt.
