## Toán tử catchError trong RxJS

**Khái niệm:**

Toán tử `catchError` là một **Error Handling Operator** trong RxJS dùng để **bắt lỗi** xảy ra trong Observable và **chuyển đổi lỗi thành một Observable mới**.

**Ngữ cảnh:**

Toán tử `catchError` thường được sử dụng trong Angular để:

* **Xử lý lỗi** xảy ra trong các tác vụ bất đồng bộ.
* **Hiển thị thông báo lỗi** cho người dùng.
* **Chuyển hướng người dùng** đến một trang khác khi xảy ra lỗi.

**Cách sử dụng:**

Toán tử `catchError` nhận một tham số:

* **Hàm xử lý lỗi**: Hàm này nhận lỗi xảy ra làm tham số và trả về một Observable mới.

Toán tử sẽ **bắt lỗi** xảy ra trong Observable, sau đó **gọi hàm xử lý lỗi** để tạo ra một Observable mới. Observable mới này sẽ được phát ra thay vì lỗi.

**Ví dụ:**

```typescript
import { of, fromEvent, catchError } from 'rxjs';

// Observable phát ra giá trị 1, 2, 3
const observable = of(1, 2, 3);

// Observable phát ra lỗi khi giá trị nhập không phải là số
const observableWithCatchError = observable.pipe(
  catchError((error) => {
    // Hiển thị thông báo lỗi cho người dùng
    console.log('Lỗi:', error.message);

    // Trả về một Observable mới phát ra giá trị '0'
    return of(0);
  }),
);

observableWithCatchError.subscribe(console.log);

// In ra:
// 1
// 2
// 3
// Lỗi: Giá trị nhập không phải là số
// 0
```

**Lưu ý:**

* Toán tử `catchError` **không thể** ngăn chặn lỗi xảy ra.
* Toán tử `catchError` chỉ có thể **bắt lỗi** và **chuyển đổi lỗi thành một Observable mới**.
* Toán tử `catchError` có thể được sử dụng kết hợp với các toán tử RxJS khác để tạo ra các luồng dữ liệu phức tạp hơn.

**Tài liệu tham khảo:**

* RxJS catchError(): [https://rxjs.dev/api/operators/catchError](https://rxjs.dev/api/operators/catchError)
* Angular RxJS: [https://angular.io/guide/rx-library](https://angular.io/guide/rx-library)

## Ví dụ nâng cao

Toán tử `catchError` có thể được sử dụng kết hợp với các toán tử RxJS khác để tạo ra các luồng dữ liệu phức tạp hơn. Ví dụ:

```typescript
import { of, fromEvent, catchError, retry } from 'rxjs';

// Observable phát ra giá trị 1, 2, 3
const observable = of(1, 2, 3);

// Observable phát ra lỗi khi giá trị nhập không phải là số
const observableWithCatchError = observable.pipe(
  catchError((error) => {
    // Hiển thị thông báo lỗi cho người dùng
    console.log('Lỗi:', error.message);

    // Thử lại 3 lần trước khi trả về lỗi
    return observable.pipe(retry(3));
  }),
);

observableWithCatchError.subscribe(console.log);

// In ra:
// 1
// 2
// 3
// Lỗi: Giá trị nhập không phải là số
// Thử lại...
// Lỗi: Giá trị nhập không phải là số
// Thử lại...
// Lỗi: Giá trị nhập không phải là số
// Lỗi: Thử lại quá nhiều lần
```

Trong ví dụ trên, chúng ta sử dụng toán tử `catchError` để **bắt lỗi** xảy ra trong Observable, sau đó **thử lại 3 lần** trước khi **trả về lỗi**.

## Kết luận

Toán tử `catchError` là một công cụ mạnh mẽ để xử lý lỗi xảy ra trong các tác vụ bất đồng bộ, hiển thị thông báo lỗi cho người dùng và chuyển hướng người dùng đến một trang khác khi xảy ra lỗi. Toán tử này giúp **giảm thiểu mã code**, **tăng hiệu quả** và **giúp xử lý các luồng dữ liệu phức tạp** trong ứng dụng.